<?xml version="1.0"?>

<robot xmlns:xacro="http://ros.org/wiki/xacro">
 <xacro:include filename="$(find gripper_description)/urdf/finger_transmission.xacro" />


  <material name="Grey">
    <color rgba="0.2 0.2 0.2 1" />
  </material>
  <material name="Blue">
    <color rgba="0 0 1 1" />
  </material>

<xacro:macro name="soft_finger" params="name parent transmission_hw_interface gripper_active *origin">

	<xacro:if value="${gripper_active}">
	  <xacro:finger_transmission name="${name}" hw_interface="${transmission_hw_interface}" />
	  
	  
	  <joint name="${name}_joint" type="revolute">
	    <parent link="${parent}"/>
	    <child link="${name}_link"/>
	    <axis xyz="1 0 0"/>
	    <xacro:insert_block name="origin"/>
	    <limit effort="50" velocity="10.0" lower="-0.5" upper="0.3" />
	  </joint>
	  
	  
	</xacro:if>

	<xacro:unless value="${gripper_active}">
	  <joint name="${name}_joint" type="fixed">
	    <parent link="${parent}"/>
	    <child link="${name}_link"/>
	    <xacro:insert_block name="origin"/>
	  </joint>
	</xacro:unless>


	<link name="${name}_link">
	<inertial>
		<origin xyz="2.073e-05   1.45286e-03  -1.1049e-03" rpy="0 0 0" />
		<mass value="0.168" />
		<inertia ixx="6.69695624e-05" ixy="5.21511788e-09" ixz="-2.74383009e-08" iyy="7.85088161e-05" iyz="5.41105193e-07" izz="1.41819717e-04" />
	</inertial>
	<visual>
	<origin rpy="0 0 0" xyz="0 0 0" />
		<geometry>
		    <mesh filename="package://gripper_description/meshes/soft_gripper_finger1.stl"/>
		</geometry>
	</visual>
	<collision>
	<origin rpy="0 0 0" xyz="0 0 0" />
		<geometry>
		    <mesh filename="package://gripper_description/meshes/soft_gripper_finger1.stl"/>
		</geometry>
	</collision>
	</link>

    
	<joint name="${name}_joint2" type="fixed">
	<origin xyz="0 0.009 0.042" rpy=" 0 0 0" />
	<parent link="${name}_link" />
	<child link="${name}_link2" />
	</joint>

	<link name="${name}_link2">
	<visual>
		<geometry>
		  <mesh filename="package://gripper_description/meshes/soft_gripper_finger2.stl" />
		</geometry>
	<material name="Blue" />
	</visual>
	<collision>
		<geometry>
		  <mesh filename="package://gripper_description/meshes/soft_gripper_finger2.stl" />
		</geometry>
	</collision>
	<inertial>
	<origin xyz="2.073e-05   1.45286e-03  -1.1049e-03" rpy="0 0 0" />
		<mass value="0.168" />
		<inertia ixx="6.69695624e-05" ixy="5.21511788e-09" ixz="-2.74383009e-08" iyy="7.85088161e-05" iyz="5.41105193e-07" izz="1.41819717e-04" />
	</inertial>
	</link>



	  <gazebo reference="${name}_link2">
		<material>Gazebo/Blue</material>
	  </gazebo>

	
	    <gazebo reference="${name}_link2">
		<material>Gazebo/Blue</material>
	  </gazebo>


	 <gazebo reference="${name}_link">
	    <collision name="${name}_link_collision">
	      <surface>
		<friction>
		  <torsional>
		    <coefficient>10.0</coefficient>
		    <use_patch_radius>true</use_patch_radius>
		    <patch_radius>0.05</patch_radius>
		  </torsional>
		</friction>
		<contact>
		  <poissons_ratio>0.5</poissons_ratio>
		  <elastic_modulus>1e8</elastic_modulus>
		</contact>
	      </surface>
	    </collision>
	    <mu1>10</mu1>
	    <mu2>10</mu2>

	    <kp>1000000.0</kp>
	    <kd>10.0</kd> 
	    <fdir1>0 0 1</fdir1>
	    <minDepth>0.001</minDepth>
		    <maxVel>0.0</maxVel>

	    <maxContacts>1</maxContacts>
	    <material>Gazebo/RedBright</material>
	  </gazebo>


</xacro:macro>
</robot>
