<?xml version="1.0" ?>
<!-- =================================================================================== -->
<!-- |    This document was autogenerated by xacro from /home/toto/ros_ws/src/UR5BlokVision/locosim/robot_descriptions/ur_description/urdf/ur5.urdf.xacro | -->
<!-- |    EDITING THIS FILE BY HAND IS NOT RECOMMENDED                                 | -->
<!-- =================================================================================== -->
<robot name="ur_robot">
    <!--
    NOTE: the macro defined in this file is NOT part of the public API of this
          package. Users CANNOT rely on this file being available, or stored in
          this location. Nor can they rely on the existence of the macro.
  -->
    <joint name="tavolo_joint" type="fixed">
        <parent link="base_link" />
        <child link="tavolo_link" />
        <origin rpy="0 0 0" xyz="-0.5 -0.35 -1.75" />
    </joint>
    <link name="tavolo_link">
        <!-- Visual geometry -->
        <visual name="visual">
            <geometry>
                <mesh filename="package://ur_description/meshes/tavolo/mesh/tavolo.stl" scale="0.001 0.001 0.001" />
            </geometry>
            <material name="LightGrey">
                <color rgba="0.7 0.7 0.7 1.0" />
            </material>
        </visual>
        <!-- Base collision -->
        <collision name="base_collision">
            <origin rpy="0 0 0" xyz="0.5 0.4 0.85" />
            <geometry>
                <box size="1 0.8 0.04" />
            </geometry>
        </collision>
        <!-- Box collision -->
        <collision name="box_collision">
            <origin rpy="0 0 0" xyz="0.5 0.08 0.95" />
            <geometry>
                <box size="1 0.15 0.15" />
            </geometry>
        </collision>
        <!-- Back collision -->
        <collision name="back_collision">
            <origin rpy="1.57 0 0" xyz="0.5 -0.02 1.35" />
            <geometry>
                <box size="1 1.0 0.04" />
            </geometry>
        </collision>
        <inertial>
            <mass value="0.1" />
            <origin xyz="0 0 0" rpy="0 0 0" />
            <inertia ixx="0.03" iyy="0.03" izz="0.03" ixy="0.0" ixz="0.0" iyz="0.0" />
        </inertial>
    </link>
    <transmission name="shoulder_pan_trans">
        <type>transmission_interface/SimpleTransmission</type>
        <joint name="shoulder_pan_joint">
            <hardwareInterface>hardware_interface/EffortJointInterface</hardwareInterface>
        </joint>
        <actuator name="shoulder_pan_motor">
            <mechanicalReduction>1</mechanicalReduction>
            <hardwareInterface>hardware_interface/EffortJointInterface</hardwareInterface>
        </actuator>
    </transmission>
    <transmission name="shoulder_lift_trans">
        <type>transmission_interface/SimpleTransmission</type>
        <joint name="shoulder_lift_joint">
            <hardwareInterface>hardware_interface/EffortJointInterface</hardwareInterface>
        </joint>
        <actuator name="shoulder_lift_motor">
            <mechanicalReduction>1</mechanicalReduction>
            <hardwareInterface>hardware_interface/EffortJointInterface</hardwareInterface>
        </actuator>
    </transmission>
    <transmission name="elbow_trans">
        <type>transmission_interface/SimpleTransmission</type>
        <joint name="elbow_joint">
            <hardwareInterface>hardware_interface/EffortJointInterface</hardwareInterface>
        </joint>
        <actuator name="elbow_motor">
            <mechanicalReduction>1</mechanicalReduction>
            <hardwareInterface>hardware_interface/EffortJointInterface</hardwareInterface>
        </actuator>
    </transmission>
    <transmission name="wrist_1_trans">
        <type>transmission_interface/SimpleTransmission</type>
        <joint name="wrist_1_joint">
            <hardwareInterface>hardware_interface/EffortJointInterface</hardwareInterface>
        </joint>
        <actuator name="wrist_1_motor">
            <mechanicalReduction>1</mechanicalReduction>
            <hardwareInterface>hardware_interface/EffortJointInterface</hardwareInterface>
        </actuator>
    </transmission>
    <transmission name="wrist_2_trans">
        <type>transmission_interface/SimpleTransmission</type>
        <joint name="wrist_2_joint">
            <hardwareInterface>hardware_interface/EffortJointInterface</hardwareInterface>
        </joint>
        <actuator name="wrist_2_motor">
            <mechanicalReduction>1</mechanicalReduction>
            <hardwareInterface>hardware_interface/EffortJointInterface</hardwareInterface>
        </actuator>
    </transmission>
    <transmission name="wrist_3_trans">
        <type>transmission_interface/SimpleTransmission</type>
        <joint name="wrist_3_joint">
            <hardwareInterface>hardware_interface/EffortJointInterface</hardwareInterface>
        </joint>
        <actuator name="wrist_3_motor">
            <mechanicalReduction>1</mechanicalReduction>
            <hardwareInterface>hardware_interface/EffortJointInterface</hardwareInterface>
        </actuator>
    </transmission>
    <!-- links: main serial chain -->
    <link name="base_link" />
    <link name="base_link_inertia">
        <visual>
            <origin rpy="0 0 3.141592653589793" xyz="0 0 0" />
            <geometry>
                <mesh filename="package://ur_description/meshes/ur5e/visual/base.dae" />
            </geometry>
            <material name="LightGrey">
                <color rgba="0.7 0.7 0.7 1.0" />
            </material>
        </visual>
        <collision>
            <origin rpy="0 0 3.141592653589793" xyz="0 0 0" />
            <geometry>
                <mesh filename="package://ur_description/meshes/ur5e/collision/base.stl" />
            </geometry>
        </collision>
        <inertial>
            <mass value="4.0" />
            <origin rpy="0 0 0" xyz="0 0 0" />
            <inertia ixx="0.00443333156" ixy="0.0" ixz="0.0" iyy="0.00443333156" iyz="0.0" izz="0.0072" />
        </inertial>
    </link>
    <link name="shoulder_link">
        <visual>
            <origin rpy="0 0 3.141592653589793" xyz="0 0 0" />
            <geometry>
                <mesh filename="package://ur_description/meshes/ur5e/visual/shoulder.dae" />
            </geometry>
            <material name="LightGrey">
                <color rgba="0.7 0.7 0.7 1.0" />
            </material>
        </visual>
        <collision>
            <origin rpy="0 0 3.141592653589793" xyz="0 0 0" />
            <geometry>
                <mesh filename="package://ur_description/meshes/ur5e/collision/shoulder.stl" />
            </geometry>
        </collision>
        <inertial>
            <mass value="3.7" />
            <origin rpy="0 0 0" xyz="0 0 0" />
            <inertia ixx="0.010267495893" ixy="0.0" ixz="0.0" iyy="0.010267495893" iyz="0.0" izz="0.00666" />
        </inertial>
    </link>
    <link name="upper_arm_link">
        <visual>
            <origin rpy="1.5707963267948966 0 -1.5707963267948966" xyz="0 0 0.138" />
            <geometry>
                <mesh filename="package://ur_description/meshes/ur5e/visual/upperarm.dae" />
            </geometry>
            <material name="LightGrey">
                <color rgba="0.7 0.7 0.7 1.0" />
            </material>
        </visual>
        <collision>
            <origin rpy="1.5707963267948966 0 -1.5707963267948966" xyz="0 0 0.138" />
            <geometry>
                <mesh filename="package://ur_description/meshes/ur5e/collision/upperarm.stl" />
            </geometry>
        </collision>
        <inertial>
            <mass value="8.393" />
            <origin rpy="0 1.5707963267948966 0" xyz="-0.2125 0.0 0.138" />
            <inertia ixx="0.1338857818623325" ixy="0.0" ixz="0.0" iyy="0.1338857818623325" iyz="0.0" izz="0.0151074" />
        </inertial>
    </link>
    <link name="forearm_link">
        <visual>
            <origin rpy="1.5707963267948966 0 -1.5707963267948966" xyz="0 0 0.007" />
            <geometry>
                <mesh filename="package://ur_description/meshes/ur5e/visual/forearm.dae" />
            </geometry>
            <material name="LightGrey">
                <color rgba="0.7 0.7 0.7 1.0" />
            </material>
        </visual>
        <collision>
            <origin rpy="1.5707963267948966 0 -1.5707963267948966" xyz="0 0 0.007" />
            <geometry>
                <mesh filename="package://ur_description/meshes/ur5e/collision/forearm.stl" />
            </geometry>
        </collision>
        <inertial>
            <mass value="2.275" />
            <origin rpy="0 1.5707963267948966 0" xyz="-0.1961 0.0 0.007" />
            <inertia ixx="0.031209355099586295" ixy="0.0" ixz="0.0" iyy="0.031209355099586295" iyz="0.0" izz="0.004095" />
        </inertial>
    </link>
    <link name="wrist_1_link">
        <visual>
            <!-- TODO: Move this to a parameter -->
            <origin rpy="1.5707963267948966 0 0" xyz="0 0 -0.127" />
            <geometry>
                <mesh filename="package://ur_description/meshes/ur5e/visual/wrist1.dae" />
            </geometry>
            <material name="LightGrey">
                <color rgba="0.7 0.7 0.7 1.0" />
            </material>
        </visual>
        <collision>
            <origin rpy="1.5707963267948966 0 0" xyz="0 0 -0.127" />
            <geometry>
                <mesh filename="package://ur_description/meshes/ur5e/collision/wrist1.stl" />
            </geometry>
        </collision>
        <inertial>
            <mass value="1.219" />
            <origin rpy="0 0 0" xyz="0 0 0" />
            <inertia ixx="0.0025598989760400002" ixy="0.0" ixz="0.0" iyy="0.0025598989760400002" iyz="0.0" izz="0.0021942" />
        </inertial>
    </link>
    <link name="wrist_2_link">
        <visual>
            <origin rpy="0 0 0" xyz="0 0 -0.0997" />
            <geometry>
                <mesh filename="package://ur_description/meshes/ur5e/visual/wrist2.dae" />
            </geometry>
            <material name="LightGrey">
                <color rgba="0.7 0.7 0.7 1.0" />
            </material>
        </visual>
        <collision>
            <origin rpy="0 0 0" xyz="0 0 -0.0997" />
            <geometry>
                <mesh filename="package://ur_description/meshes/ur5e/collision/wrist2.stl" />
            </geometry>
        </collision>
        <inertial>
            <mass value="1.219" />
            <origin rpy="0 0 0" xyz="0 0 0" />
            <inertia ixx="0.0025598989760400002" ixy="0.0" ixz="0.0" iyy="0.0025598989760400002" iyz="0.0" izz="0.0021942" />
        </inertial>
    </link>
    <link name="wrist_3_link">
        <visual>
            <origin rpy="1.5707963267948966 0 0" xyz="0 0 -0.0989" />
            <geometry>
                <mesh filename="package://ur_description/meshes/ur5e/visual/wrist3.dae" />
            </geometry>
            <material name="LightGrey">
                <color rgba="0.7 0.7 0.7 1.0" />
            </material>
        </visual>
        <collision>
            <origin rpy="1.5707963267948966 0 0" xyz="0 0 -0.0989" />
            <geometry>
                <mesh filename="package://ur_description/meshes/ur5e/collision/wrist3.stl" />
            </geometry>
        </collision>
        <inertial>
            <mass value="0.1879" />
            <origin rpy="0 0 0" xyz="0.0 0.0 -0.0229" />
            <inertia ixx="9.890410052167731e-05" ixy="0.0" ixz="0.0" iyy="9.890410052167731e-05" iyz="0.0" izz="0.0001321171875" />
        </inertial>
    </link>
    <!-- joints: main serial chain -->
    <joint name="base_link-base_link_inertia" type="fixed">
        <parent link="base_link" />
        <child link="base_link_inertia" />
        <!-- 'base_link' is REP-103 aligned (so X+ forward), while the internal
           frames of the robot/controller have X+ pointing backwards.
           Use the joint between 'base_link' and 'base_link_inertia' (a dummy
           link/frame) to introduce the necessary rotation over Z (of pi rad).
      -->
        <origin rpy="3.141592653589793 0 0" xyz="0 0 0" />
    </joint>
    <joint name="shoulder_pan_joint" type="revolute">
        <parent link="base_link_inertia" />
        <child link="shoulder_link" />
        <origin rpy="0 0 0" xyz="0 0 0.1625" />
        <axis xyz="0 0 1" />
        <limit effort="150.0" lower="-6.14" upper="6.14" velocity="3.14" />
        <dynamics damping="0" friction="0" />
    </joint>
    <joint name="shoulder_lift_joint" type="revolute">
        <parent link="shoulder_link" />
        <child link="upper_arm_link" />
        <origin rpy="1.570796327 0 0" xyz="0 0 0" />
        <axis xyz="0 0 1" />
        <limit effort="150.0" lower="-3.14" upper="0" velocity="3.14" />
        <dynamics damping="0" friction="0" />
    </joint>
    <joint name="elbow_joint" type="revolute">
        <parent link="upper_arm_link" />
        <child link="forearm_link" />
        <origin rpy="0 0 0" xyz="-0.425 0 0" />
        <axis xyz="0 0 1" />
        <limit effort="150.0" lower="-3.14" upper="3.14" velocity="3.14" />
        <dynamics damping="0" friction="0" />
    </joint>
    <joint name="wrist_1_joint" type="revolute">
        <parent link="forearm_link" />
        <child link="wrist_1_link" />
        <origin rpy="0 0 0" xyz="-0.3922 0 0.1333" />
        <axis xyz="0 0 1" />
        <limit effort="28.0" lower="-6.28" upper="6.28" velocity="3.14" />
        <dynamics damping="0" friction="0" />
    </joint>
    <joint name="wrist_2_joint" type="revolute">
        <parent link="wrist_1_link" />
        <child link="wrist_2_link" />
        <origin rpy="1.570796327 0 0" xyz="0 -0.0997 -2.044881182297852e-11" />
        <axis xyz="0 0 1" />
        <limit effort="28.0" lower="-6.28" upper="6.28" velocity="3.14" />
        <dynamics damping="0" friction="0" />
    </joint>
    <joint name="wrist_3_joint" type="revolute">
        <parent link="wrist_2_link" />
        <child link="wrist_3_link" />
        <origin rpy="1.570796326589793 3.141592653589793 3.141592653589793" xyz="0 0.0996 -2.042830148012698e-11" />
        <axis xyz="0 0 1" />
        <limit effort="28.0" lower="-6.28" upper="6.28" velocity="3.14" />
        <dynamics damping="0" friction="0" />
    </joint>
    <!-- ROS-Industrial 'base' frame: base_link to UR 'Base' Coordinates transform -->
    <link name="base" />
    <joint name="base_link-base_fixed_joint" type="fixed">
        <!-- Note the rotation over Z of pi radians: as base_link is REP-103
           aligned (ie: has X+ forward, Y+ left and Z+ up), this is needed
           to correctly align 'base' with the 'Base' coordinate system of
           the UR controller.
      -->
        <origin rpy="0 0 3.141592653589793" xyz="0 0 0" />
        <parent link="base_link" />
        <child link="base" />
    </joint>
    <!-- ROS-Industrial 'flange' frame: attachment point for EEF models -->
    <link name="flange" />
    <joint name="wrist_3-flange" type="fixed">
        <parent link="wrist_3_link" />
        <child link="flange" />
        <origin rpy="0 -1.5707963267948966 -1.5707963267948966" xyz="0 0 0" />
    </joint>
    <!-- ROS-Industrial 'tool0' frame: all-zeros tool frame -->
    <link name="tool0_without_gripper" />
    <joint name="flange-tool0" type="fixed">
        <!-- default toolframe: X+ left, Y+ up, Z+ front -->
        <origin rpy="1.5707963267948966 0 1.5707963267948966" xyz="0 0 0" />
        <parent link="flange" />
        <child link="tool0_without_gripper" />
    </joint>
    <!-- fixed frames for collisions (potential fields)-->
    <link name="upper_arm_link_middle" />
    <joint name="upper_arm_link_middle_fixed_joint" type="fixed">
        <origin rpy="0 0 0" xyz="-0.2125 0 0.13" />
        <parent link="upper_arm_link" />
        <child link="upper_arm_link_middle" />
    </joint>
    <link name="forearm_link_middle" />
    <joint name="forearm_link_middle_fixed_joint" type="fixed">
        <origin rpy="0 0 0" xyz="-0.2125 0.0 0.0" />
        <parent link="forearm_link" />
        <child link="forearm_link_middle" />
    </joint>
    <link name="forearm_link_end" />
    <joint name="forearm_link_end_fixed_joint" type="fixed">
        <origin rpy="0 0 0" xyz="-0.425 0 0" />
        <parent link="forearm_link" />
        <child link="forearm_link_end" />
    </joint>
    <link name="gripper_base_down">
        <inertial>
            <origin rpy="0 0 0" xyz="0.0 0.0 0.0" />
            <mass value="1.0" />
            <inertia ixx="0.01" ixy="0.0" ixz="0.0" iyy="0.01" iyz="0.0" izz="0.01" />
        </inertial>
        <visual>
            <origin rpy="-1.5707963267948966 0 0" xyz="0 0 0" />
            <geometry>
                <mesh filename="package://gripper_description/meshes/gripper_base_down.stl" scale="0.001 0.001 0.001" />
            </geometry>
        </visual>
        <collision>
            <origin rpy="-1.5707963267948966 0 0" xyz="0 0 0" />
            <geometry>
                <mesh filename="package://gripper_description/meshes/gripper_base_down.stl" scale="0.001 0.001 0.001" />
            </geometry>
        </collision>
    </link>
    <link name="gripper_base">
        <visual>
            <origin rpy="-1.5707963267948966 0 0" xyz="0.2275 0 0 " />
            <geometry>
                <mesh filename="package://gripper_description/meshes/gripper_base_up.stl" scale="0.001 0.001 0.001" />
            </geometry>
        </visual>
        <collision>
            <origin rpy="-1.5707963267948966 0 0" xyz="0.2275 0 0" />
            <geometry>
                <mesh filename="package://gripper_description/meshes/gripper_base_up.stl" scale="0.001 0.001 0.001" />
            </geometry>
        </collision>
        <inertial>
            <mass value="0.1" />
            <origin xyz="0 0 0" rpy="0 0 0" />
            <inertia ixx="0.03" iyy="0.03" izz="0.03" ixy="0.0" ixz="0.0" iyz="0.0" />
        </inertial>
    </link>
    <joint name="flange" type="fixed">
        <origin rpy="0 0 0" xyz="0 0 0.06" />
        <parent link="gripper_base" />
        <child link="gripper_base_down" />
    </joint>
    <joint name="fixed_ee_gripper" type="fixed">
        <origin rpy="0 0 0" xyz="0 0 0.12" />
        <parent link="gripper_base" />
        <child link="tool0" />
    </joint>
    <link name="tool0" />
    <joint name="hand_1_joint" type="fixed">
        <parent link="gripper_base_down" />
        <child link="hand_1_link" />
        <origin rpy="-1.5707963267948966 0 0" xyz="0.0  -0.03 0.05" />
    </joint>
    <link name="hand_1_link">
        <inertial>
            <origin xyz="0.0 0.0 0.0" rpy="0 0 0" />
            <mass value="0.05" />
            <inertia ixx="0.001" ixy="0.0" ixz="0.0" iyy="0.001" iyz="0.0" izz="0.001" />
        </inertial>
        <visual>
            <origin rpy="0 0 0" xyz="0 0.05 0.03" />
            <geometry>
                <mesh filename="package://gripper_description/meshes/finger.stl" scale="0.001 0.001 0.001" />
            </geometry>
        </visual>
        <collision>
            <origin rpy="0 0 0" xyz="0 0.05 0.03" />
            <geometry>
                <mesh filename="package://gripper_description/meshes/finger.stl" scale="0.001 0.001 0.001" />
            </geometry>
        </collision>
    </link>
    <gazebo reference="hand_1_link">
        <collision name="hand_1_link_collision">
            <surface>
                <friction>
                    <torsional>
                        <coefficient>10.0</coefficient>
                        <use_patch_radius>true</use_patch_radius>
                        <patch_radius>0.05</patch_radius>
                    </torsional>
                </friction>
                <contact>
                    <poissons_ratio>0.5</poissons_ratio>
                    <elastic_modulus>1e8</elastic_modulus>
                </contact>
            </surface>
        </collision>
        <mu1>10</mu1>
        <mu2>10</mu2>
        <kp>1000000.0</kp>
        <kd>10.0</kd>
        <fdir1>0 0 1</fdir1>
        <minDepth>0.001</minDepth>
        <maxVel>0.0</maxVel>
        <maxContacts>1</maxContacts>
        <material>Gazebo/RedBright</material>
        <plugin name="gazebo_ros_control">
            <robotNamespace>/</robotNamespace>
        </plugin>
    </gazebo>
    <joint name="hand_2_joint" type="fixed">
        <parent link="gripper_base_down" />
        <child link="hand_2_link" />
        <origin rpy="-1.5707963267948966 0 2.0943951023931953" xyz="0.02598 0.015 0.05" />
    </joint>
    <link name="hand_2_link">
        <inertial>
            <origin xyz="0.0 0.0 0.0" rpy="0 0 0" />
            <mass value="0.05" />
            <inertia ixx="0.001" ixy="0.0" ixz="0.0" iyy="0.001" iyz="0.0" izz="0.001" />
        </inertial>
        <visual>
            <origin rpy="0 0 0" xyz="0 0.05 0.03" />
            <geometry>
                <mesh filename="package://gripper_description/meshes/finger.stl" scale="0.001 0.001 0.001" />
            </geometry>
        </visual>
        <collision>
            <origin rpy="0 0 0" xyz="0 0.05 0.03" />
            <geometry>
                <mesh filename="package://gripper_description/meshes/finger.stl" scale="0.001 0.001 0.001" />
            </geometry>
        </collision>
    </link>
    <gazebo reference="hand_2_link">
        <collision name="hand_2_link_collision">
            <surface>
                <friction>
                    <torsional>
                        <coefficient>10.0</coefficient>
                        <use_patch_radius>true</use_patch_radius>
                        <patch_radius>0.05</patch_radius>
                    </torsional>
                </friction>
                <contact>
                    <poissons_ratio>0.5</poissons_ratio>
                    <elastic_modulus>1e8</elastic_modulus>
                </contact>
            </surface>
        </collision>
        <mu1>10</mu1>
        <mu2>10</mu2>
        <kp>1000000.0</kp>
        <kd>10.0</kd>
        <fdir1>0 0 1</fdir1>
        <minDepth>0.001</minDepth>
        <maxVel>0.0</maxVel>
        <maxContacts>1</maxContacts>
        <material>Gazebo/RedBright</material>
    </gazebo>
    <joint name="hand_3_joint" type="fixed">
        <parent link="gripper_base_down" />
        <child link="hand_3_link" />
        <origin rpy="-1.5707963267948966 0 -2.0943951023931953" xyz="-0.02598 0.015 0.05" />
    </joint>
    <link name="hand_3_link">
        <inertial>
            <origin xyz="0.0 0.0 0.0" rpy="0 0 0" />
            <mass value="0.05" />
            <inertia ixx="0.001" ixy="0.0" ixz="0.0" iyy="0.001" iyz="0.0" izz="0.001" />
        </inertial>
        <visual>
            <origin rpy="0 0 0" xyz="0 0.05 0.03" />
            <geometry>
                <mesh filename="package://gripper_description/meshes/finger.stl" scale="0.001 0.001 0.001" />
            </geometry>
        </visual>
        <collision>
            <origin rpy="0 0 0" xyz="0 0.05 0.03" />
            <geometry>
                <mesh filename="package://gripper_description/meshes/finger.stl" scale="0.001 0.001 0.001" />
            </geometry>
        </collision>
    </link>
    <gazebo reference="hand_3_link">
        <collision name="hand_3_link_collision">
            <surface>
                <friction>
                    <torsional>
                        <coefficient>10.0</coefficient>
                        <use_patch_radius>true</use_patch_radius>
                        <patch_radius>0.05</patch_radius>
                    </torsional>
                </friction>
                <contact>
                    <poissons_ratio>0.5</poissons_ratio>
                    <elastic_modulus>1e8</elastic_modulus>
                </contact>
            </surface>
        </collision>
        <mu1>10</mu1>
        <mu2>10</mu2>
        <kp>1000000.0</kp>
        <kd>10.0</kd>
        <fdir1>0 0 1</fdir1>
        <minDepth>0.001</minDepth>
        <maxVel>0.0</maxVel>
        <maxContacts>1</maxContacts>
        <material>Gazebo/RedBright</material>
    </gazebo>
    <joint name="gripper_robot_joint" type="fixed">
        <parent link="tool0_without_gripper" />
        <child link="gripper_base" />
        <origin rpy="0 0 1.57" xyz="0 0 0" />
    </joint>
    <!-- camera body, with origin at bottom screw mount -->
    <joint name="zed_camera_fixed_joint" type="fixed">
        <origin rpy="0. 0.523 0." xyz="-0.9 0.18 -0.35" />
        <parent link="base_link" />
        <child link="zed2_camera_center" />
    </joint>
    <!-- Camera Center -->
    <link name="zed2_camera_center">
        <inertial>
            <mass value="0.16140" />
            <origin xyz="0 0 0" rpy="0 0 0" />
            <inertia ixx="0.0003947" ixy="0.0" ixz="3.3365e-8" iyy="2.417e-5" iyz="0.0" izz="0.0003973" />
        </inertial>
        <visual>
            <geometry>
                <mesh filename="package://ur_description/sensors/zed2/simulation/ZED2.dae" />
            </geometry>
        </visual>
        <collision>
            <geometry>
                <mesh filename="package://ur_description/sensors/zed2/simulation/ZED2.dae" />
            </geometry>
        </collision>
    </link>
    <!-- Left Camera -->
    <joint name="zed2_left_camera_joint" type="fixed">
        <parent link="zed2_camera_center" />
        <child link="zed2_left_camera_frame" />
        <origin rpy="0 0 0" xyz="0 0.06 0" />
    </joint>
    <link name="zed2_left_camera_frame" />
    <joint name="zed2_left_camera_optical_joint" type="fixed">
        <origin rpy="-1.5707963267948966 0.0 -1.5707963267948966" xyz="0 0 0" />
        <parent link="zed2_left_camera_frame" />
        <child link="zed2_left_camera_optical_frame" />
    </joint>
    <link name="zed2_left_camera_optical_frame" />
    <!-- Right Camera -->
    <joint name="zed2_right_camera_joint" type="fixed">
        <parent link="zed2_camera_center" />
        <child link="zed2_right_camera_frame" />
        <origin rpy="0 0 0" xyz="0 -0.06 0" />
    </joint>
    <link name="zed2_right_camera_frame" />
    <joint name="zed2_right_camera_optical_joint" type="fixed">
        <origin rpy="-1.5707963267948966 0.0 -1.5707963267948966" xyz="0 0 0" />
        <parent link="zed2_right_camera_frame" />
        <child link="zed2_right_camera_optical_frame" />
    </joint>
    <link name="zed2_right_camera_optical_frame" />
    <!-- Sensors -->
    <joint name="zed2_mag_joint" type="fixed">
        <parent link="zed2_camera_center" />
        <child link="zed2_mag_link" />
        <origin rpy="0 0 0" xyz="0 0 0" />
    </joint>
    <link name="zed2_mag_link" />
    <joint name="zed2_baro_joint" type="fixed">
        <parent link="zed2_camera_center" />
        <child link="zed2_baro_link" />
        <origin rpy="0 0 0" xyz="0 0 0" />
    </joint>
    <link name="zed2_baro_link" />
    <joint name="zed2_temp_left_joint" type="fixed">
        <parent link="zed2_left_camera_frame" />
        <child link="zed2_temp_left_link" />
        <origin rpy="0 0 0" xyz="0 0 0" />
    </joint>
    <link name="zed2_temp_left_link" />
    <joint name="zed2_temp_right_joint" type="fixed">
        <parent link="zed2_right_camera_frame" />
        <child link="zed2_temp_right_link" />
        <origin rpy="0 0 0" xyz="0 0 0" />
    </joint>
    <link name="zed2_temp_right_link" />
    <!-- Left/Depth camera -->
    <gazebo reference="zed2_left_camera_frame">
        <!-- Raw images (with lens distortion) -->
        <sensor name="zed2_left_raw_camera" type="camera">
            <always_on>true</always_on>
            <update_rate>15.0</update_rate>
            <visualize>false</visualize>
            <camera name="zed2_left_raw">
                <horizontal_fov>1.7633</horizontal_fov>
                <image>
                    <width>1920</width>
                    <height>1080</height>
                    <format>R8G8B8</format>
                </image>
                <clip>
                    <near>0.02</near>
                    <far>300</far>
                </clip>
                <noise>
                    <type>gaussian</type>
                    <mean>0.0</mean>
                    <stddev>0.007</stddev>
                </noise>
                <distortion>
                    <!-- Values copied from an actual ZED2 camera -->
                    <k1>-0.043693598</k1>
                    <k2>0.0146164996</k2>
                    <p1>-0.006573319</p1>
                    <p2>-0.000216900</p2>
                    <k3>0.000084328</k3>
                    <center>0.5 0.5</center>
                </distortion>
            </camera>
            <plugin filename="libgazebo_ros_camera.so" name="camera_controller">
                <robotNamespace />
                <cameraName>zed_node/left_raw</cameraName>
                <imageTopicName>image_raw_color</imageTopicName>
                <cameraInfoTopicName>camera_info</cameraInfoTopicName>
                <frameName>zed2_left_camera_optical_frame</frameName>
                <distortionK1>-0.043693598</distortionK1>
                <distortionK2>0.0146164996</distortionK2>
                <distortionT1>-0.006573319</distortionT1>
                <distortionT2>-0.000216900</distortionT2>
                <distortionK3>0.000084328</distortionK3>
                <CxPrime>640</CxPrime>
                <Cx>640</Cx>
                <Cy>360</Cy>
                <hackBaseline>0.0</hackBaseline>
            </plugin>
        </sensor>
        <sensor name="zed2_left_camera" type="depth">
            <!-- Rectified images, Depth images, Point Clouds -->
            <always_on>true</always_on>
            <update_rate>15.0</update_rate>
            <visualize>false</visualize>
            <camera name="zed2_left">
                <horizontal_fov>1.7633</horizontal_fov>
                <image>
                    <width>1920</width>
                    <height>1080</height>
                    <format>R8G8B8</format>
                </image>
                <clip>
                    <near>0.02</near>
                    <far>300</far>
                </clip>
                <noise>
                    <type>gaussian</type>
                    <mean>0.0</mean>
                    <stddev>0.007</stddev>
                </noise>
            </camera>
            <plugin filename="libgazebo_ros_openni_kinect.so" name="camera_controller">
                <robotNamespace />
                <cameraName>zed_node</cameraName>
                <imageTopicName>left/image_rect_color</imageTopicName>
                <cameraInfoTopicName>left/camera_info</cameraInfoTopicName>
                <depthImageTopicName>depth/depth_registered</depthImageTopicName>
                <depthImageInfoTopicName>depth/camera_info</depthImageInfoTopicName>
                <pointCloudTopicName>point_cloud/cloud_registered</pointCloudTopicName>
                <pointCloudCutoff>0.1</pointCloudCutoff>
                <pointCloudCutoffMax>20.0</pointCloudCutoffMax>
                <frameName>zed2_left_camera_optical_frame</frameName>
                <baseline>0.12</baseline>
                <CxPrime>640</CxPrime>
                <Cx>640</Cx>
                <Cy>360</Cy>
                <hackBaseline>0.0</hackBaseline>
            </plugin>
        </sensor>
    </gazebo>
    <!-- Right camera -->
    <gazebo reference="zed2_right_camera_frame">
        <!-- Raw images (with lens distortion) -->
        <sensor name="zed2_right_raw_camera" type="camera">
            <always_on>true</always_on>
            <update_rate>15.0</update_rate>
            <visualize>false</visualize>
            <camera name="zed2_right_raw">
                <horizontal_fov>1.7633</horizontal_fov>
                <image>
                    <width>1920</width>
                    <height>1080</height>
                    <format>R8G8B8</format>
                </image>
                <clip>
                    <near>0.02</near>
                    <far>300</far>
                </clip>
                <noise>
                    <type>gaussian</type>
                    <mean>0.0</mean>
                    <stddev>0.007</stddev>
                </noise>
                <distortion>
                    <k1>-0.040993299</k1>
                    <k2>0.009593590</k2>
                    <p1>-0.004429849</p1>
                    <p2>0.000192024</p2>
                    <k3>-0.000320880</k3>
                    <center>0.5 0.5</center>
                </distortion>
            </camera>
            <plugin filename="libgazebo_ros_camera.so" name="camera_controller">
                <robotNamespace />
                <cameraName>zed_node/right_raw</cameraName>
                <imageTopicName>image_raw_color</imageTopicName>
                <cameraInfoTopicName>camera_info</cameraInfoTopicName>
                <frameName>zed2_right_camera_optical_frame</frameName>
                <distortionK1>-0.040993299</distortionK1>
                <distortionK2>0.009593590</distortionK2>
                <distortionT1>-0.004429849</distortionT1>
                <distortionT2>0.000192024</distortionT2>
                <distortionK3>-0.000320880</distortionK3>
                <CxPrime>640</CxPrime>
                <Cx>640</Cx>
                <Cy>360</Cy>
                <hackBaseline>0.12</hackBaseline>
            </plugin>
        </sensor>
        <sensor name="zed2_right_camera" type="camera">
            <!-- Rectified images -->
            <always_on>true</always_on>
            <update_rate>15.0</update_rate>
            <visualize>false</visualize>
            <camera name="zed2_right">
                <horizontal_fov>1.7633</horizontal_fov>
                <image>
                    <width>1920</width>
                    <height>1080</height>
                    <format>R8G8B8</format>
                </image>
                <clip>
                    <near>0.02</near>
                    <far>300</far>
                </clip>
                <noise>
                    <type>gaussian</type>
                    <mean>0.0</mean>
                    <stddev>0.007</stddev>
                </noise>
            </camera>
            <plugin filename="libgazebo_ros_camera.so" name="camera_controller">
                <robotNamespace />
                <cameraName>zed_node/right</cameraName>
                <imageTopicName>image_rect_color</imageTopicName>
                <cameraInfoTopicName>camera_info</cameraInfoTopicName>
                <frameName>zed2_right_camera_optical_frame</frameName>
                <CxPrime>640</CxPrime>
                <Cx>640</Cx>
                <Cy>360</Cy>
                <hackBaseline>0.12</hackBaseline>
            </plugin>
        </sensor>
    </gazebo>
    <!-- IMU -->
    <gazebo reference="zed2_left_camera_frame">
        <sensor name="zed2_imu_sensor" type="imu">
            <update_rate>100</update_rate>
            <plugin filename="libgazebo_ros_imu_sensor.so" name="imu_plugin">
                <robotNamespace />
                <topicName>/ur5/zed_node/imu/data</topicName>
                <frameName>zed2_imu_link</frameName>
                <updateRateHZ>100.0</updateRateHZ>
                <gaussianNoise>0.01</gaussianNoise>
                <initialOrientationAsReference>false</initialOrientationAsReference>
                <!-- IMU frame offset copied from an actual ZED2 camera -->
                <xyzOffset>-0.002 -0.023 -0.002</xyzOffset>
                <rpyOffset>0.0014025 -0.0000012 -0.0016915</rpyOffset>
            </plugin>
        </sensor>
    </gazebo>
    <!--	<xacro:include filename="$(find ur_description)/sensors/d435_camera.urdf.xacro"/>-->
    <!--	  &lt;!&ndash; realsense &ndash;&gt;-->
    <!--	  &lt;!&ndash;These values are taken from  d435_camera.urdf.xacro and  d435_camera_openni.gazebo.urdf.xacro in sensors-description-->
    <!--	 repo, commit 3fb6f787&ndash;&gt;-->
    <!--	  <xacro:property name="camera_fov" value="3.0"/>-->
    <!--	  <xacro:property name="camera_width" value="640"/> -->
    <!--	  <xacro:property name="camera_height" value="480"/>-->
    <!--	  <xacro:property name="camera_near" value="0.1"/>-->
    <!--	  <xacro:property name="camera_far" value="100"/>    -->
    <!--	  <xacro:property name="m_camera" value="0.07"/> &lt;!&ndash;??&ndash;&gt;-->
    <!--	<xacro:d435_camera -->
    <!--		parent="wrist_3_link" -->
    <!--		name="ee_camera"-->
    <!--		camera_plugin="true">  -->
    <!--		<origin xyz="0.05 0.0 -0.02" rpy="0 -1.57 0.0"/>-->
    <!--	</xacro:d435_camera>-->
    <!--	  -->
    <!--	  -->
    <!--	  <xacro:property name="camera_fov" value="3.0"/>-->
    <!--	  <xacro:property name="camera_width" value="640"/> -->
    <!--	  <xacro:property name="camera_height" value="480"/>-->
    <!--	  <xacro:property name="camera_near" value="0.01"/>-->
    <!--	  <xacro:property name="camera_far" value="100"/> -->
    <!--	<xacro:d435_camera -->
    <!--		parent="base_link" -->
    <!--		name="z_base_camera"-->
    <!--		camera_plugin="true">  -->
    <!--		<origin xyz="0.0 -0.3 -0.5" rpy="0.0  0.5 1.57"/>-->
    <!--	</xacro:d435_camera>-->
    <link name="world" />
    <joint name="world_joint" type="fixed">
        <parent link="world" />
        <child link="base_link" />
        <origin rpy="0 0 0" xyz="0.5 0.35 1.75" />
    </joint>
    <!--
    Attach the Gazebo model to Gazebo's world frame.

    Note: if you're looking to integrate a UR into a larger scene and need
    to add EEFs or other parts, DO NOT change this file or the 'world' link
    here. Create a NEW xacro instead and decide whether you need to add
    a 'world' link there.
  -->
    <!-- Configure self collision properties per link -->
    <gazebo reference="shoulder_link">
        <selfCollide>true</selfCollide>
    </gazebo>
    <gazebo reference="upper_arm_link">
        <selfCollide>true</selfCollide>
    </gazebo>
    <gazebo reference="forearm_link">
        <selfCollide>true</selfCollide>
    </gazebo>
    <gazebo reference="wrist_1_link">
        <selfCollide>true</selfCollide>
    </gazebo>
    <gazebo reference="wrist_3_link">
        <selfCollide>true</selfCollide>
    </gazebo>
    <gazebo reference="wrist_2_link">
        <selfCollide>true</selfCollide>
    </gazebo>
    <gazebo reference="ee_link">
        <selfCollide>true</selfCollide>
    </gazebo>
    <!-- fix me https://answers.gazebosim.org//question/15095/gazebo-contact-sensor-added-to-a-robot-link-in-urdf-file-is-not-working-as-expected/-->
    <!--gazebo reference="$(arg prefix)wrist_3_link">
		<kp>1000000.0</kp>
		<kd>100.0</kd>
		<mu1>1.0</mu1>
		<mu2>1.0</mu2>
		<maxVel>1.0</maxVel>
		<maxContacts>1</maxContacts>
		<sensor name="ee_contact_sensor" type="contact">
			<always_on>true</always_on>
			<update_rate>250.0</update_rate>
			<contact>
				<collision>$(arg prefix)wrist_3_link_collision_collision</collision>
			</contact>
		        <plugin name="gazebo_ros_bumper_controller" filename="libgazebo_ros_bumper.so">
				<bumperTopicName>/ur5/wrench</bumperTopicName>	
				<frameName>$(arg prefix)wrist_3_link</frameName>		
		        	<robotNamespace>ur5</robotNamespace>
			</plugin>
		</sensor>
	</gazebo-->
    <!--
      Inject Gazebo ROS Control plugin, which allows us to use ros_control
      controllers to control the virtual robot hw.
    -->
    <gazebo>
        <plugin filename="libgazebo_ros_control.so" name="gazebo_ros_controller_manager">
            <robotNamespace>ur5</robotNamespace>
            <!--TODO1 change this with prefix when you use 2 robots     -->
            <robotSimType>gazebo_ros_control/DefaultRobotHWSim</robotSimType>
            <robotParam>ur5/robot_description</robotParam>
            <legacyModeNS>true</legacyModeNS>
        </plugin>
    </gazebo>
</robot>

